<?xml version='1.0'?>

<robot name="wheelchair" xmlns:xacro="http://www.ros.org/wiki/xacro">

    <!-- Motor, Camera and Lidar Simulation -->
	<!--<xacro:include filename="$(find wheelchair)/urdf/wheelchair.gazebo" />-->

	<xacro:property name="robot_name" value="wheelchair" />
	<xacro:property name="chassis_mass" value="50"/>
	<xacro:property name="upper_chassis_mass" value="20"/>
	<xacro:property name="middle_wheel_mass" value="10"/>
	<xacro:property name="middle_wheel_radius" value="0.128"/>
	<xacro:property name="rear_wheel_radius" value="0.060"/>
	<xacro:property name="rear_wheel_length" value="0.025"/>
	<xacro:property name="rear_wheel_mass" value="3"/>
	<xacro:property name="rear_wheel_support_mass" value="2"/>

	<!-- Axis Values-->
	<xacro:property name="z_wheel_support" value="0.125"/>
	<xacro:property name="z_back_wheel" value="0.062"/>
	<xacro:property name="z_back_diff" value="-0.063"/> <!-- Equals to: (z_back_wheel - z_wheel_support) -->
	<xacro:property name="x_wheel_support" value="0.083"/>
	<xacro:property name="x_back_wheel" value="0.06"/>
	<xacro:property name="x_back_diff" value="-0.023"/> <!-- Equals to: (x_back_wheel - x_wheel_support) -->
	<xacro:property name="y_right_wheels_and_support" value="0.051"/>
	<xacro:property name="y_left_wheels_and_support" value="0.527"/>
	<xacro:property name="x_upper_chassis" value="0.42"/>
	<xacro:property name="y_upper_chassis" value="0.29"/>
	<xacro:property name="z_upper_chassis" value="0.4"/>

	<!-- Make Chassis of Bot -->
	<link name="chassis">

		<pose>0 0 0.1 0 0 0</pose>

		<inertial>
			<mass value="${chassis_mass}"/>
      		<origin xyz="0.35 0.29 0.2" rpy=" 0 0 0"/>

      		<inertia 
      			ixx="0.147116667" ixy="0" ixz="0"
      			iyy="0.334951167" iyz="0"
      			izz="0.3978345"
      		/>
		</inertial>

		<collision name="collision">
			<origin xyz="0 0 0" rpy=" 0 0 0"/>
			<geometry>
				<mesh filename="package://wheelchair/meshes/chassis_motor.dae"/>
			</geometry>
		</collision>

		<visual name="chassis_visual">
			<origin xyz="0 0 0" rpy=" 0 0 0"/>
			<geometry>
                <mesh filename="package://wheelchair/meshes/chassis_motor.dae"/>
			</geometry>
		</visual>

	</link>

	<link name="upper_chassis">

		<inertial>
			<mass value="${upper_chassis_mass}"/>
      		<origin xyz="0 0 0" rpy=" 0 0 0"/>

      		<inertia 
      			ixx="0.147116667" ixy="0" ixz="0"
      			iyy="0.334951167" iyz="0"
      			izz="0.3978345"
      		/>
		</inertial>

		<collision>
			<origin xyz="-${x_upper_chassis} -${y_upper_chassis} -${z_upper_chassis}" rpy="0 0 0"/>
			<geometry>
				<mesh filename="package://wheelchair/meshes/upper_chassis.dae"/>
			</geometry>
		</collision>

		<visual>
			<origin xyz="-${x_upper_chassis} -${y_upper_chassis} -${z_upper_chassis}" rpy="0 0 0"/>
			<geometry>
				<mesh filename="package://wheelchair/meshes/upper_chassis.dae"/>
			</geometry>
		</visual>

	</link>

	<!-- Left Wheel -->
	<link name="left_wheel">

		<inertial>
			<mass value="${middle_wheel_mass}"/>
			<origin xyz="0 0 0" rpy="0 1.5707 1.5707"/>
			<inertia
				ixx="0.1" ixy="0.0" ixz="0.0"
				iyy="0.1" iyz="0.0"
				izz="0.1"
			/>
		</inertial>

		<collision>
			<origin xyz="0 0 0" rpy="0 1.5707 1.5707"/>
			<geometry>
				<cylinder radius="${middle_wheel_radius}" length="0.05"/>
			</geometry>
		</collision>

		<visual>
			<origin xyz="-0.523 -${y_left_wheels_and_support} -0.13" rpy="0 0 0"/>
			<geometry>
				<mesh filename="package://wheelchair/meshes/middle_wheel_left.dae"/>
			</geometry>
		</visual>

	</link>

	<!-- Right Wheel -->
	<link name="right_wheel">

		<inertial>
			<mass value="${middle_wheel_mass}"/>
			<origin xyz="0 0 0" rpy="0 1.5707 1.5707"/>
			<inertia
			ixx="0.1" ixy="0.0" ixz="0.0"
			iyy="0.1" iyz="0.0"
			izz="0.1"
			/>
		</inertial>

		<collision>
			<origin xyz="0 0 0" rpy="0 1.5707 1.5707"/>
			<geometry>
				<cylinder radius="${middle_wheel_radius}" length="0.05"/>
			</geometry>
		</collision>

		<visual>
			<origin xyz="-0.523 -${y_right_wheels_and_support} -0.13" rpy="0 0 0"/>
			<geometry>
				<mesh filename="package://wheelchair/meshes/middle_wheel_right.dae"/>
			</geometry>
		</visual>

	</link>

	<!-- Right Wheel Back -->
	<link name="right_wheel_back">

		<inertial>
			<mass value="${rear_wheel_mass}"/>
			<origin xyz="0 0 0" rpy="0 1.5707 1.5707"/>
			<inertia
				ixx="0.1" ixy="0.0" ixz="0.0"
				iyy="0.1" iyz="0.0"
				izz="0.1"
			/>
		</inertial>

		<collision>
			<origin xyz="0 0 0" rpy="0 1.5707 1.5707"/>
			<geometry>
				<cylinder radius="${rear_wheel_radius}" length="${rear_wheel_length}"/>
			</geometry>
		</collision>

		<visual>
			<origin xyz="-${x_back_wheel} -${y_right_wheels_and_support} -${z_back_wheel}" rpy="0 0 0"/>
			<geometry>
				<mesh filename="package://wheelchair/meshes/right_wheel_back.dae"/>
			</geometry>
		</visual>

	</link>

	<!-- Left Wheel Back -->
	<link name="left_wheel_back">

		<inertial>
			<mass value="${rear_wheel_mass}"/>
			<origin xyz="0 0 0" rpy="0 1.5707 1.5707"/>
			<inertia
				ixx="0.1" ixy="0.0" ixz="0.0"
				iyy="0.1" iyz="0.0"
				izz="0.1"
			/>
		</inertial>

		<collision>
			<origin xyz="0 0 0" rpy="0 1.5707 1.5707"/>
			<geometry>
				<cylinder radius="${rear_wheel_radius}" length="${rear_wheel_length}"/>
			</geometry>
		</collision>

		<visual>
			<origin xyz="-${x_back_wheel} -${y_left_wheels_and_support} -${z_back_wheel}" rpy="0 0 0"/>
			<geometry>
				<mesh filename="package://wheelchair/meshes/left_wheel_back.dae"/>
			</geometry>
		</visual>

	</link>


	<!-- Left Wheel Support -->
	<link name="left_wheel_support">

		<inertial>
			<mass value="${rear_wheel_support_mass}"/>
			<origin xyz="0 0 0" rpy="0 0 0"/>
			<inertia
				ixx="0.1" ixy="0.0" ixz="0.0"
				iyy="0.1" iyz="0.0"
				izz="0.1"
			/>
		</inertial>

		<collision>
			<origin xyz="-${x_wheel_support} -${y_left_wheels_and_support} -${z_wheel_support}" rpy="0 0 0"/>
			<geometry>
				<mesh filename="package://wheelchair/meshes/left_wheel_support.dae"/>
			</geometry>
		</collision>

		<visual>
			<origin xyz="-${x_wheel_support} -${y_left_wheels_and_support} -${z_wheel_support}" rpy="0 0 0"/>
			<geometry>
				<mesh filename="package://wheelchair/meshes/left_wheel_support.dae"/>
			</geometry>
		</visual>

	</link>

	<!-- Right Wheel Support -->
	<link name="right_wheel_support">

		<inertial>
			<mass value="${rear_wheel_support_mass}"/>
			<origin xyz="0 0 0" rpy="0 0 0"/>
			<inertia
				ixx="0.1" ixy="0.0" ixz="0.0"
				iyy="0.1" iyz="0.0"
				izz="0.1"
			/>
		</inertial>

		<collision>
			<origin xyz="-${x_wheel_support} -${y_right_wheels_and_support} -${z_wheel_support}" rpy="0 0 0"/>
			<geometry>
				<mesh filename="package://wheelchair/meshes/right_wheel_support.dae"/>
			</geometry>
		</collision>

		<visual>
			<origin xyz="-${x_wheel_support} -${y_right_wheels_and_support} -${z_wheel_support}" rpy="0 0 0"/>
			<geometry>
				<mesh filename="package://wheelchair/meshes/right_wheel_support.dae"/>
			</geometry>
		</visual>

	</link>

	<!-- Project center to the ground -->
	<link name="robot_footprint"></link>

	<!-- ******** Define Joints ********** -->

	<joint name="robot_footprint_joint" type="fixed">
		<origin xyz="0 0 0" rpy="0 0 0" />
		<parent link="robot_footprint"/>
		<child link="chassis" />
	</joint>

	<joint type="prismatic" name="upper_chassis_joint">
		<origin xyz="${x_upper_chassis} ${y_upper_chassis} 0.37" rpy="0 0 0" />
		<parent link="chassis"/>
		<child link="upper_chassis" />
		<axis xyz="0 0 1"/>
		<limit effort="10000" lower="0.0" upper="0.045" velocity="0.01"/>
  	</joint>

	<joint type="continuous" name="left_wheel_front_joint">
		<origin xyz="0.523 ${y_left_wheels_and_support} 0.13" rpy="0 0 0" />
		<parent link="chassis"/>
		<child link="left_wheel" />
		<axis xyz="0 1 0" rpy="0 0 0" />
		<limit effort="10000" velocity="1000" />
		<dynamics damping="1.0" friction="1.0" />
  	</joint>

	<joint type="continuous" name="right_wheel_front_joint">
		<origin xyz="0.523 ${y_right_wheels_and_support} 0.13" rpy="0 0 0" />
		<parent link="chassis"/>
		<child link="right_wheel" />
		<axis xyz="0 1 0" rpy="0 0 0" />
		<limit effort="10000" velocity="1000" />
		<dynamics damping="1.0" friction="1.0" />
  	</joint>

	<joint type="continuous" name="right_wheel_support_joint">
		<origin xyz="${x_wheel_support} ${y_right_wheels_and_support} ${z_wheel_support}" rpy="0 0 0" />
		<parent link="chassis"/>
		<child link="right_wheel_support" />
		<axis xyz="0 0 1" rpy="0 0 0" />
		<limit effort="10000" velocity="1000" />
		<dynamics damping="1.0" friction="1.0" />
  	</joint>

	<joint type="continuous" name="left_wheel_support_joint">
		<origin xyz="${x_wheel_support} ${y_left_wheels_and_support} ${z_wheel_support}" rpy="0 0 0" />
		<parent link="chassis"/>
		<child link="left_wheel_support" />
		<axis xyz="0 0 1" rpy="0 0 0" />
		<limit effort="10000" velocity="1000" />
		<dynamics damping="1.0" friction="1.0" />
  	</joint>

	<joint type="continuous" name="rear_left_wheel_joint">
		<origin xyz="${x_back_diff} 0 ${z_back_diff}" rpy="0 0 0" />
		<parent link="left_wheel_support"/>
		<child link="left_wheel_back" />
		<axis xyz="0 1 0" rpy="0 0 0" />
		<limit effort="10000" velocity="1000" />
		<dynamics damping="1.0" friction="1.0" />
  	</joint>

	<joint type="continuous" name="rear_right_wheel_joint">
		<origin xyz="${x_back_diff} 0 ${z_back_diff}" rpy="0 0 0" />
		<parent link="right_wheel_support"/>
		<child link="right_wheel_back" />
		<axis xyz="0 1 0" rpy="0 0 0" />
		<limit effort="10000" velocity="1000"/>
		<dynamics damping="1.0" friction="1.0" />
  	</joint>

	<!-- ******** Define Transmissions ********** -->

	<transmission name="upper_chassis_trans">
		<type>transmission_interface/SimpleTransmission</type>
		<actuator name="upper_chassis_motor">
			<hardwareInterface>EffortJointInterface</hardwareInterface>
			<mechanicalReduction>1</mechanicalReduction>
		</actuator>
		<joint name="upper_chassis_joint">
			<hardwareInterface>EffortJointInterface</hardwareInterface>
		</joint>
 	</transmission>

	<transmission name="left_wheel_trans">
		<type>transmission_interface/SimpleTransmission</type>
		<actuator name="left_wheel_motor">
			<hardwareInterface>EffortJointInterface</hardwareInterface>
			<mechanicalReduction>1</mechanicalReduction>
		</actuator>
		<joint name="left_wheel_front_joint">
			<hardwareInterface>VelocityJointInterface</hardwareInterface>
		</joint>
 	</transmission>

	<transmission name="right_wheel_trans">
		<type>transmission_interface/SimpleTransmission</type>
		<actuator name="right_wheel_motor">
			<hardwareInterface>EffortJointInterface</hardwareInterface>
			<mechanicalReduction>1</mechanicalReduction>
		</actuator>
		<joint name="right_wheel_front_joint">
			<hardwareInterface>VelocityJointInterface</hardwareInterface>
		</joint>
 	</transmission>


	 <!-- Add ROS plugin so we can interact with our robot -->
	<gazebo>
		<plugin name="gazebo_ros_control" filename="libgazebo_ros_control.so">
		<robotNamespace>/</robotNamespace>
		</plugin>
	</gazebo>

</robot>